Workbook

Sheet Controle de Skins
A1: Nome da Skin | B1: Categoria | C1: Preço de Compra (R$) | D1: Preço de Venda Bruto (R$) | E1: Taxa (6%) | F1: Receita Líquida (R$) | G1: Lucro (R$) | H1: ROI (%)
A2: Survival Marble Fade | B2: {=_xlfn.IFS(OR(ISNUMBER(SEARCH("survival",A2)),ISNUMBER(SEARCH("nomad",A2)),ISNUMBER(SEARCH("bayonet",A2)),ISNUMBER(SEARCH("falchion",A2)),ISNUMBER(SEARCH("m9 ",A2)),ISNUMBER(SEARCH("butterfly",A2)),ISNUMBER(SEARCH("skeleton",A2)),ISNUMBER(SEARCH("paracord",A2)),ISNUMBER(SEARCH("classic",A2))), "Knives", OR(ISNUMBER(SEARCH("glove",A2))), "Gloves", OR(ISNUMBER(SEARCH("sticker",A2)),AND(ISNUMBER(SEARCH("fallen",A2)),NOT(ISNUMBER(SEARCH("awp",A2))),NOT(ISNUMBER(SEARCH("ak",A2))))), "Sticker", OR(ISNUMBER(SEARCH("ak ",A2)),ISNUMBER(SEARCH("ak-",A2)),ISNUMBER(SEARCH("m4a1",A2)),ISNUMBER(SEARCH("m4a4",A2)),ISNUMBER(SEARCH("galil",A2)),ISNUMBER(SEARCH("famas",A2))), "Rifles", OR(ISNUMBER(SEARCH("awp",A2)),ISNUMBER(SEARCH("ssg",A2))), "Sniper", OR(ISNUMBER(SEARCH("usp",A2)),ISNUMBER(SEARCH("glock",A2)),ISNUMBER(SEARCH("eagle",A2)),ISNUMBER(SEARCH("p250",A2)),ISNUMBER(SEARCH("berettas",A2))), "Pistol", TRUE, "SMG")} -> Knives | C2: 1215 | D2: 1500 | E2: =IF(D2>0, D2*0.06, "") -> 90 | F2: =IF(D2>0, D2-E2, "") -> 1410 | G2: =IF(AND(C2>0,F2>0), F2-C2, "") -> 195 | H2: =IF(C2>0, ROUND(G2/C2*100, 0), "") -> 16
A3: Survival Rust Coat | B3: {=_xlfn.IFS(OR(ISNUMBER(SEARCH("survival",A3)),ISNUMBER(SEARCH("nomad",A3)),ISNUMBER(SEARCH("bayonet",A3)),ISNUMBER(SEARCH("falchion",A3)),ISNUMBER(SEARCH("m9 ",A3)),ISNUMBER(SEARCH("butterfly",A3)),ISNUMBER(SEARCH("skeleton",A3)),ISNUMBER(SEARCH("paracord",A3)),ISNUMBER(SEARCH("classic",A3))), "Knives", OR(ISNUMBER(SEARCH("glove",A3))), "Gloves", OR(ISNUMBER(SEARCH("sticker",A3)),AND(ISNUMBER(SEARCH("fallen",A3)),NOT(ISNUMBER(SEARCH("awp",A3))),NOT(ISNUMBER(SEARCH("ak",A3))))), "Sticker", OR(ISNUMBER(SEARCH("ak ",A3)),ISNUMBER(SEARCH("ak-",A3)),ISNUMBER(SEARCH("m4a1",A3)),ISNUMBER(SEARCH("m4a4",A3)),ISNUMBER(SEARCH("galil",A3)),ISNUMBER(SEARCH("famas",A3))), "Rifles", OR(ISNUMBER(SEARCH("awp",A3)),ISNUMBER(SEARCH("ssg",A3))), "Sniper", OR(ISNUMBER(SEARCH("usp",A3)),ISNUMBER(SEARCH("glock",A3)),ISNUMBER(SEARCH("eagle",A3)),ISNUMBER(SEARCH("p250",A3)),ISNUMBER(SEARCH("berettas",A3))), "Pistol", TRUE, "SMG")} -> Knives | C3: 490 | D3: 600 | E3: =IF(D3>0, D3*0.06, "") -> 36 | F3: =IF(D3>0, D3-E3, "") -> 564 | G3: =IF(AND(C3>0,F3>0), F3-C3, "") -> 74 | H3: =IF(C3>0, ROUND(G3/C3*100, 0), "") -> 15
A4: Ak Inheritance | B4: {=_xlfn.IFS(OR(ISNUMBER(SEARCH("survival",A4)),ISNUMBER(SEARCH("nomad",A4)),ISNUMBER(SEARCH("bayonet",A4)),ISNUMBER(SEARCH("falchion",A4)),ISNUMBER(SEARCH("m9 ",A4)),ISNUMBER(SEARCH("butterfly",A4)),ISNUMBER(SEARCH("skeleton",A4)),ISNUMBER(SEARCH("paracord",A4)),ISNUMBER(SEARCH("classic",A4))), "Knives", OR(ISNUMBER(SEARCH("glove",A4))), "Gloves", OR(ISNUMBER(SEARCH("sticker",A4)),AND(ISNUMBER(SEARCH("fallen",A4)),NOT(ISNUMBER(SEARCH("awp",A4))),NOT(ISNUMBER(SEARCH("ak",A4))))), "Sticker", OR(ISNUMBER(SEARCH("ak ",A4)),ISNUMBER(SEARCH("ak-",A4)),ISNUMBER(SEARCH("m4a1",A4)),ISNUMBER(SEARCH("m4a4",A4)),ISNUMBER(SEARCH("galil",A4)),ISNUMBER(SEARCH("famas",A4))), "Rifles", OR(ISNUMBER(SEARCH("awp",A4)),ISNUMBER(SEARCH("ssg",A4))), "Sniper", OR(ISNUMBER(SEARCH("usp",A4)),ISNUMBER(SEARCH("glock",A4)),ISNUMBER(SEARCH("eagle",A4)),ISNUMBER(SEARCH("p250",A4)),ISNUMBER(SEARCH("berettas",A4))), "Pistol", TRUE, "SMG")} -> Rifles | C4: 315 | D4: 385 | E4: =IF(D4>0, D4*0.06, "") -> 23.1 | F4: =IF(D4>0, D4-E4, "") -> 361.9 | G4: =IF(AND(C4>0,F4>0), F4-C4, "") -> 46.9 | H4: =IF(C4>0, G4/C4*100, "") -> 14.888889
A5: Sticker Fallen Gold | B5: {=_xlfn.IFS(OR(ISNUMBER(SEARCH("survival",A5)),ISNUMBER(SEARCH("nomad",A5)),ISNUMBER(SEARCH("bayonet",A5)),ISNUMBER(SEARCH("falchion",A5)),ISNUMBER(SEARCH("m9 ",A5)),ISNUMBER(SEARCH("butterfly",A5)),ISNUMBER(SEARCH("skeleton",A5)),ISNUMBER(SEARCH("paracord",A5)),ISNUMBER(SEARCH("classic",A5))), "Knives", OR(ISNUMBER(SEARCH("glove",A5))), "Gloves", OR(ISNUMBER(SEARCH("sticker",A5)),AND(ISNUMBER(SEARCH("fallen",A5)),NOT(ISNUMBER(SEARCH("awp",A5))),NOT(ISNUMBER(SEARCH("ak",A5))))), "Sticker", OR(ISNUMBER(SEARCH("ak ",A5)),ISNUMBER(SEARCH("ak-",A5)),ISNUMBER(SEARCH("m4a1",A5)),ISNUMBER(SEARCH("m4a4",A5)),ISNUMBER(SEARCH("galil",A5)),ISNUMBER(SEARCH("famas",A5))), "Rifles", OR(ISNUMBER(SEARCH("awp",A5)),ISNUMBER(SEARCH("ssg",A5))), "Sniper", OR(ISNUMBER(SEARCH("usp",A5)),ISNUMBER(SEARCH("glock",A5)),ISNUMBER(SEARCH("eagle",A5)),ISNUMBER(SEARCH("p250",A5)),ISNUMBER(SEARCH("berettas",A5))), "Pistol", TRUE, "SMG")} -> Sticker | C5: 42 | D5: 94 | E5: =IF(D5>0, D5*0.06, "") -> 5.64 | F5: =IF(D5>0, D5-E5, "") -> 88.36 | G5: =IF(AND(C5>0,F5>0), F5-C5, "") -> 46.36 | H5: =IF(C5>0, G5/C5*100, "") -> 110.38095
A6: Sticker Fallen Gold | B6: {=_xlfn.IFS(OR(ISNUMBER(SEARCH("survival",A6)),ISNUMBER(SEARCH("nomad",A6)),ISNUMBER(SEARCH("bayonet",A6)),ISNUMBER(SEARCH("falchion",A6)),ISNUMBER(SEARCH("m9 ",A6)),ISNUMBER(SEARCH("butterfly",A6)),ISNUMBER(SEARCH("skeleton",A6)),ISNUMBER(SEARCH("paracord",A6)),ISNUMBER(SEARCH("classic",A6))), "Knives", OR(ISNUMBER(SEARCH("glove",A6))), "Gloves", OR(ISNUMBER(SEARCH("sticker",A6)),AND(ISNUMBER(SEARCH("fallen",A6)),NOT(ISNUMBER(SEARCH("awp",A6))),NOT(ISNUMBER(SEARCH("ak",A6))))), "Sticker", OR(ISNUMBER(SEARCH("ak ",A6)),ISNUMBER(SEARCH("ak-",A6)),ISNUMBER(SEARCH("m4a1",A6)),ISNUMBER(SEARCH("m4a4",A6)),ISNUMBER(SEARCH("galil",A6)),ISNUMBER(SEARCH("famas",A6))), "Rifles", OR(ISNUMBER(SEARCH("awp",A6)),ISNUMBER(SEARCH("ssg",A6))), "Sniper", OR(ISNUMBER(SEARCH("usp",A6)),ISNUMBER(SEARCH("glock",A6)),ISNUMBER(SEARCH("eagle",A6)),ISNUMBER(SEARCH("p250",A6)),ISNUMBER(SEARCH("berettas",A6))), "Pistol", TRUE, "SMG")} -> Sticker | C6: 42 | D6: 94 | E6: =IF(D6>0, D6*0.06, "") -> 5.64 | F6: =IF(D6>0, D6-E6, "") -> 88.36 | G6: =IF(AND(C6>0,F6>0), F6-C6, "") -> 46.36 | H6: =IF(C6>0, G6/C6*100, "") -> 110.38095
A7: Sticker Fallen Gold | B7: {=_xlfn.IFS(OR(ISNUMBER(SEARCH("survival",A7)),ISNUMBER(SEARCH("nomad",A7)),ISNUMBER(SEARCH("bayonet",A7)),ISNUMBER(SEARCH("falchion",A7)),ISNUMBER(SEARCH("m9 ",A7)),ISNUMBER(SEARCH("butterfly",A7)),ISNUMBER(SEARCH("skeleton",A7)),ISNUMBER(SEARCH("paracord",A7)),ISNUMBER(SEARCH("classic",A7))), "Knives", OR(ISNUMBER(SEARCH("glove",A7))), "Gloves", OR(ISNUMBER(SEARCH("sticker",A7)),AND(ISNUMBER(SEARCH("fallen",A7)),NOT(ISNUMBER(SEARCH("awp",A7))),NOT(ISNUMBER(SEARCH("ak",A7))))), "Sticker", OR(ISNUMBER(SEARCH("ak ",A7)),ISNUMBER(SEARCH("ak-",A7)),ISNUMBER(SEARCH("m4a1",A7)),ISNUMBER(SEARCH("m4a4",A7)),ISNUMBER(SEARCH("galil",A7)),ISNUMBER(SEARCH("famas",A7))), "Rifles", OR(ISNUMBER(SEARCH("awp",A7)),ISNUMBER(SEARCH("ssg",A7))), "Sniper", OR(ISNUMBER(SEARCH("usp",A7)),ISNUMBER(SEARCH("glock",A7)),ISNUMBER(SEARCH("eagle",A7)),ISNUMBER(SEARCH("p250",A7)),ISNUMBER(SEARCH("berettas",A7))), "Pistol", TRUE, "SMG")} -> Sticker | C7: 43 | D7: 96 | E7: =IF(D7>0, D7*0.06, "") -> 5.76 | F7: =IF(D7>0, D7-E7, "") -> 90.24 | G7: =IF(AND(C7>0,F7>0), F7-C7, "") -> 47.24 | H7: =IF(C7>0, G7/C7*100, "") -> 109.86047
A8: Sticker Fallen Holo | B8: {=_xlfn.IFS(OR(ISNUMBER(SEARCH("survival",A8)),ISNUMBER(SEARCH("nomad",A8)),ISNUMBER(SEARCH("bayonet",A8)),ISNUMBER(SEARCH("falchion",A8)),ISNUMBER(SEARCH("m9 ",A8)),ISNUMBER(SEARCH("butterfly",A8)),ISNUMBER(SEARCH("skeleton",A8)),ISNUMBER(SEARCH("paracord",A8)),ISNUMBER(SEARCH("classic",A8))), "Knives", OR(ISNUMBER(SEARCH("glove",A8))), "Gloves", OR(ISNUMBER(SEARCH("sticker",A8)),AND(ISNUMBER(SEARCH("fallen",A8)),NOT(ISNUMBER(SEARCH("awp",A8))),NOT(ISNUMBER(SEARCH("ak",A8))))), "Sticker", OR(ISNUMBER(SEARCH("ak ",A8)),ISNUMBER(SEARCH("ak-",A8)),ISNUMBER(SEARCH("m4a1",A8)),ISNUMBER(SEARCH("m4a4",A8)),ISNUMBER(SEARCH("galil",A8)),ISNUMBER(SEARCH("famas",A8))), "Rifles", OR(ISNUMBER(SEARCH("awp",A8)),ISNUMBER(SEARCH("ssg",A8))), "Sniper", OR(ISNUMBER(SEARCH("usp",A8)),ISNUMBER(SEARCH("glock",A8)),ISNUMBER(SEARCH("eagle",A8)),ISNUMBER(SEARCH("p250",A8)),ISNUMBER(SEARCH("berettas",A8))), "Pistol", TRUE, "SMG")} -> Sticker | C8: 24 | D8: 50 | E8: =IF(D8>0, D8*0.06, "") -> 3 | F8: =IF(D8>0, D8-E8, "") -> 47 | G8: =IF(AND(C8>0,F8>0), F8-C8, "") -> 23 | H8: =IF(C8>0, G8/C8*100, "") -> 95.833333
A9: Sticker Fallen Holo | B9: {=_xlfn.IFS(OR(ISNUMBER(SEARCH("survival",A9)),ISNUMBER(SEARCH("nomad",A9)),ISNUMBER(SEARCH("bayonet",A9)),ISNUMBER(SEARCH("falchion",A9)),ISNUMBER(SEARCH("m9 ",A9)),ISNUMBER(SEARCH("butterfly",A9)),ISNUMBER(SEARCH("skeleton",A9)),ISNUMBER(SEARCH("paracord",A9)),ISNUMBER(SEARCH("classic",A9))), "Knives", OR(ISNUMBER(SEARCH("glove",A9))), "Gloves", OR(ISNUMBER(SEARCH("sticker",A9)),AND(ISNUMBER(SEARCH("fallen",A9)),NOT(ISNUMBER(SEARCH("awp",A9))),NOT(ISNUMBER(SEARCH("ak",A9))))), "Sticker", OR(ISNUMBER(SEARCH("ak ",A9)),ISNUMBER(SEARCH("ak-",A9)),ISNUMBER(SEARCH("m4a1",A9)),ISNUMBER(SEARCH("m4a4",A9)),ISNUMBER(SEARCH("galil",A9)),ISNUMBER(SEARCH("famas",A9))), "Rifles", OR(ISNUMBER(SEARCH("awp",A9)),ISNUMBER(SEARCH("ssg",A9))), "Sniper", OR(ISNUMBER(SEARCH("usp",A9)),ISNUMBER(SEARCH("glock",A9)),ISNUMBER(SEARCH("eagle",A9)),ISNUMBER(SEARCH("p250",A9)),ISNUMBER(SEARCH("berettas",A9))), "Pistol", TRUE, "SMG")} -> Sticker | C9: 24 | D9: 50 | E9: =IF(D9>0, D9*0.06, "") -> 3 | F9: =IF(D9>0, D9-E9, "") -> 47 | G9: =IF(AND(C9>0,F9>0), F9-C9, "") -> 23 | H9: =IF(C9>0, G9/C9*100, "") -> 95.833333
A10: Sticker Fallen Holo | B10: {=_xlfn.IFS(OR(ISNUMBER(SEARCH("survival",A10)),ISNUMBER(SEARCH("nomad",A10)),ISNUMBER(SEARCH("bayonet",A10)),ISNUMBER(SEARCH("falchion",A10)),ISNUMBER(SEARCH("m9 ",A10)),ISNUMBER(SEARCH("butterfly",A10)),ISNUMBER(SEARCH("skeleton",A10)),ISNUMBER(SEARCH("paracord",A10)),ISNUMBER(SEARCH("classic",A10))), "Knives", OR(ISNUMBER(SEARCH("glove",A10))), "Gloves", OR(ISNUMBER(SEARCH("sticker",A10)),AND(ISNUMBER(SEARCH("fallen",A10)),NOT(ISNUMBER(SEARCH("awp",A10))),NOT(ISNUMBER(SEARCH("ak",A10))))), "Sticker", OR(ISNUMBER(SEARCH("ak ",A10)),ISNUMBER(SEARCH("ak-",A10)),ISNUMBER(SEARCH("m4a1",A10)),ISNUMBER(SEARCH("m4a4",A10)),ISNUMBER(SEARCH("galil",A10)),ISNUMBER(SEARCH("famas",A10))), "Rifles", OR(ISNUMBER(SEARCH("awp",A10)),ISNUMBER(SEARCH("ssg",A10))), "Sniper", OR(ISNUMBER(SEARCH("usp",A10)),ISNUMBER(SEARCH("glock",A10)),ISNUMBER(SEARCH("eagle",A10)),ISNUMBER(SEARCH("p250",A10)),ISNUMBER(SEARCH("berettas",A10))), "Pistol", TRUE, "SMG")} -> Sticker | C10: 24 | D10: 50 | E10: =IF(D10>0, D10*0.06, "") -> 3 | F10: =IF(D10>0, D10-E10, "") -> 47 | G10: =IF(AND(C10>0,F10>0), F10-C10, "") -> 23 | H10: =IF(C10>0, G10/C10*100, "") -> 95.833333
A11: Sticker Fallen Holo | B11: {=_xlfn.IFS(OR(ISNUMBER(SEARCH("survival",A11)),ISNUMBER(SEARCH("nomad",A11)),ISNUMBER(SEARCH("bayonet",A11)),ISNUMBER(SEARCH("falchion",A11)),ISNUMBER(SEARCH("m9 ",A11)),ISNUMBER(SEARCH("butterfly",A11)),ISNUMBER(SEARCH("skeleton",A11)),ISNUMBER(SEARCH("paracord",A11)),ISNUMBER(SEARCH("classic",A11))), "Knives", OR(ISNUMBER(SEARCH("glove",A11))), "Gloves", OR(ISNUMBER(SEARCH("sticker",A11)),AND(ISNUMBER(SEARCH("fallen",A11)),NOT(ISNUMBER(SEARCH("awp",A11))),NOT(ISNUMBER(SEARCH("ak",A11))))), "Sticker", OR(ISNUMBER(SEARCH("ak ",A11)),ISNUMBER(SEARCH("ak-",A11)),ISNUMBER(SEARCH("m4a1",A11)),ISNUMBER(SEARCH("m4a4",A11)),ISNUMBER(SEARCH("galil",A11)),ISNUMBER(SEARCH("famas",A11))), "Rifles", OR(ISNUMBER(SEARCH("awp",A11)),ISNUMBER(SEARCH("ssg",A11))), "Sniper", OR(ISNUMBER(SEARCH("usp",A11)),ISNUMBER(SEARCH("glock",A11)),ISNUMBER(SEARCH("eagle",A11)),ISNUMBER(SEARCH("p250",A11)),ISNUMBER(SEARCH("berettas",A11))), "Pistol", TRUE, "SMG")} -> Sticker | C11: 25 | D11: 52 | E11: =IF(D11>0, D11*0.06, "") -> 3.12 | F11: =IF(D11>0, D11-E11, "") -> 48.88 | G11: =IF(AND(C11>0,F11>0), F11-C11, "") -> 23.88 | H11: =IF(C11>0, G11/C11*100, "") -> 95.52
A12: Survival Rust Coat | B12: {=_xlfn.IFS(OR(ISNUMBER(SEARCH("survival",A12)),ISNUMBER(SEARCH("nomad",A12)),ISNUMBER(SEARCH("bayonet",A12)),ISNUMBER(SEARCH("falchion",A12)),ISNUMBER(SEARCH("m9 ",A12)),ISNUMBER(SEARCH("butterfly",A12)),ISNUMBER(SEARCH("skeleton",A12)),ISNUMBER(SEARCH("paracord",A12)),ISNUMBER(SEARCH("classic",A12))), "Knives", OR(ISNUMBER(SEARCH("glove",A12))), "Gloves", OR(ISNUMBER(SEARCH("sticker",A12)),AND(ISNUMBER(SEARCH("fallen",A12)),NOT(ISNUMBER(SEARCH("awp",A12))),NOT(ISNUMBER(SEARCH("ak",A12))))), "Sticker", OR(ISNUMBER(SEARCH("ak ",A12)),ISNUMBER(SEARCH("ak-",A12)),ISNUMBER(SEARCH("m4a1",A12)),ISNUMBER(SEARCH("m4a4",A12)),ISNUMBER(SEARCH("galil",A12)),ISNUMBER(SEARCH("famas",A12))), "Rifles", OR(ISNUMBER(SEARCH("awp",A12)),ISNUMBER(SEARCH("ssg",A12))), "Sniper", OR(ISNUMBER(SEARCH("usp",A12)),ISNUMBER(SEARCH("glock",A12)),ISNUMBER(SEARCH("eagle",A12)),ISNUMBER(SEARCH("p250",A12)),ISNUMBER(SEARCH("berettas",A12))), "Pistol", TRUE, "SMG")} -> Knives | C12: 470 | D12: 650 | E12: =IF(D12>0, D12*0.06, "") -> 39 | F12: =IF(D12>0, D12-E12, "") -> 611 | G12: =IF(AND(C12>0,F12>0), F12-C12, "") -> 141 | H12: =IF(C12>0, G12/C12*100, "") -> 30
A13: Survival Rust Coat | B13: {=_xlfn.IFS(OR(ISNUMBER(SEARCH("survival",A13)),ISNUMBER(SEARCH("nomad",A13)),ISNUMBER(SEARCH("bayonet",A13)),ISNUMBER(SEARCH("falchion",A13)),ISNUMBER(SEARCH("m9 ",A13)),ISNUMBER(SEARCH("butterfly",A13)),ISNUMBER(SEARCH("skeleton",A13)),ISNUMBER(SEARCH("paracord",A13)),ISNUMBER(SEARCH("classic",A13))), "Knives", OR(ISNUMBER(SEARCH("glove",A13))), "Gloves", OR(ISNUMBER(SEARCH("sticker",A13)),AND(ISNUMBER(SEARCH("fallen",A13)),NOT(ISNUMBER(SEARCH("awp",A13))),NOT(ISNUMBER(SEARCH("ak",A13))))), "Sticker", OR(ISNUMBER(SEARCH("ak ",A13)),ISNUMBER(SEARCH("ak-",A13)),ISNUMBER(SEARCH("m4a1",A13)),ISNUMBER(SEARCH("m4a4",A13)),ISNUMBER(SEARCH("galil",A13)),ISNUMBER(SEARCH("famas",A13))), "Rifles", OR(ISNUMBER(SEARCH("awp",A13)),ISNUMBER(SEARCH("ssg",A13))), "Sniper", OR(ISNUMBER(SEARCH("usp",A13)),ISNUMBER(SEARCH("glock",A13)),ISNUMBER(SEARCH("eagle",A13)),ISNUMBER(SEARCH("p250",A13)),ISNUMBER(SEARCH("berettas",A13))), "Pistol", TRUE, "SMG")} -> Knives | C13: 470 | D13: 580 | E13: =IF(D13>0, D13*0.06, "") -> 34.8 | F13: =IF(D13>0, D13-E13, "") -> 545.2 | G13: =IF(AND(C13>0,F13>0), F13-C13, "") -> 75.2 | H13: =IF(C13>0, G13/C13*100, "") -> 16
A14: Survival Marble Fade | B14: {=_xlfn.IFS(OR(ISNUMBER(SEARCH("survival",A14)),ISNUMBER(SEARCH("nomad",A14)),ISNUMBER(SEARCH("bayonet",A14)),ISNUMBER(SEARCH("falchion",A14)),ISNUMBER(SEARCH("m9 ",A14)),ISNUMBER(SEARCH("butterfly",A14)),ISNUMBER(SEARCH("skeleton",A14)),ISNUMBER(SEARCH("paracord",A14)),ISNUMBER(SEARCH("classic",A14))), "Knives", OR(ISNUMBER(SEARCH("glove",A14))), "Gloves", OR(ISNUMBER(SEARCH("sticker",A14)),AND(ISNUMBER(SEARCH("fallen",A14)),NOT(ISNUMBER(SEARCH("awp",A14))),NOT(ISNUMBER(SEARCH("ak",A14))))), "Sticker", OR(ISNUMBER(SEARCH("ak ",A14)),ISNUMBER(SEARCH("ak-",A14)),ISNUMBER(SEARCH("m4a1",A14)),ISNUMBER(SEARCH("m4a4",A14)),ISNUMBER(SEARCH("galil",A14)),ISNUMBER(SEARCH("famas",A14))), "Rifles", OR(ISNUMBER(SEARCH("awp",A14)),ISNUMBER(SEARCH("ssg",A14))), "Sniper", OR(ISNUMBER(SEARCH("usp",A14)),ISNUMBER(SEARCH("glock",A14)),ISNUMBER(SEARCH("eagle",A14)),ISNUMBER(SEARCH("p250",A14)),ISNUMBER(SEARCH("berettas",A14))), "Pistol", TRUE, "SMG")} -> Knives | C14: 1220 | D14: 1450 | E14: =IF(D14 >0, D14 *0.06, "") -> 87 | F14: =IF(D14 >0, D14 -E14, "") -> 1363 | G14: =IF(AND(C14>0,F14>0), F14-C14, "") -> 143 | H14: =IF(C14>0, G14/C14*100, "") -> 11.721311
A15: Sticker Fallen Holo | B15: {=_xlfn.IFS(OR(ISNUMBER(SEARCH("survival",A15)),ISNUMBER(SEARCH("nomad",A15)),ISNUMBER(SEARCH("bayonet",A15)),ISNUMBER(SEARCH("falchion",A15)),ISNUMBER(SEARCH("m9 ",A15)),ISNUMBER(SEARCH("butterfly",A15)),ISNUMBER(SEARCH("skeleton",A15)),ISNUMBER(SEARCH("paracord",A15)),ISNUMBER(SEARCH("classic",A15))), "Knives", OR(ISNUMBER(SEARCH("glove",A15))), "Gloves", OR(ISNUMBER(SEARCH("sticker",A15)),AND(ISNUMBER(SEARCH("fallen",A15)),NOT(ISNUMBER(SEARCH("awp",A15))),NOT(ISNUMBER(SEARCH("ak",A15))))), "Sticker", OR(ISNUMBER(SEARCH("ak ",A15)),ISNUMBER(SEARCH("ak-",A15)),ISNUMBER(SEARCH("m4a1",A15)),ISNUMBER(SEARCH("m4a4",A15)),ISNUMBER(SEARCH("galil",A15)),ISNUMBER(SEARCH("famas",A15))), "Rifles", OR(ISNUMBER(SEARCH("awp",A15)),ISNUMBER(SEARCH("ssg",A15))), "Sniper", OR(ISNUMBER(SEARCH("usp",A15)),ISNUMBER(SEARCH("glock",A15)),ISNUMBER(SEARCH("eagle",A15)),ISNUMBER(SEARCH("p250",A15)),ISNUMBER(SEARCH("berettas",A15))), "Pistol", TRUE, "SMG")} -> Sticker | C15: 35 | D15: 90 | E15: =IF(D15 >0, D15 *0.06, "") -> 5.4 | F15: =IF(D15 >0, D15 -E15, "") -> 84.6 | G15: =IF(AND(C15>0,F15>0), F15-C15, "") -> 49.6 | H15: =IF(C15>0, G15/C15*100, "") -> 141.71429
A16: Survival Rust Coat | B16: {=_xlfn.IFS(OR(ISNUMBER(SEARCH("survival",A16)),ISNUMBER(SEARCH("nomad",A16)),ISNUMBER(SEARCH("bayonet",A16)),ISNUMBER(SEARCH("falchion",A16)),ISNUMBER(SEARCH("m9 ",A16)),ISNUMBER(SEARCH("butterfly",A16)),ISNUMBER(SEARCH("skeleton",A16)),ISNUMBER(SEARCH("paracord",A16)),ISNUMBER(SEARCH("classic",A16))), "Knives", OR(ISNUMBER(SEARCH("glove",A16))), "Gloves", OR(ISNUMBER(SEARCH("sticker",A16)),AND(ISNUMBER(SEARCH("fallen",A16)),NOT(ISNUMBER(SEARCH("awp",A16))),NOT(ISNUMBER(SEARCH("ak",A16))))), "Sticker", OR(ISNUMBER(SEARCH("ak ",A16)),ISNUMBER(SEARCH("ak-",A16)),ISNUMBER(SEARCH("m4a1",A16)),ISNUMBER(SEARCH("m4a4",A16)),ISNUMBER(SEARCH("galil",A16)),ISNUMBER(SEARCH("famas",A16))), "Rifles", OR(ISNUMBER(SEARCH("awp",A16)),ISNUMBER(SEARCH("ssg",A16))), "Sniper", OR(ISNUMBER(SEARCH("usp",A16)),ISNUMBER(SEARCH("glock",A16)),ISNUMBER(SEARCH("eagle",A16)),ISNUMBER(SEARCH("p250",A16)),ISNUMBER(SEARCH("berettas",A16))), "Pistol", TRUE, "SMG")} -> Knives | C16: 485 | D16: 550 | E16: =IF(D16 >0, D16 *0.06, "") -> 33 | F16: =IF(D16 >0, D16 -E16, "") -> 517 | G16: =IF(AND(C16>0,F16>0), F16-C16, "") -> 32 | H16: =IF(C16>0, G16/C16*100, "") -> 6.5979381
A17: Nomad Rust Coat | B17: {=_xlfn.IFS(OR(ISNUMBER(SEARCH("survival",A17)),ISNUMBER(SEARCH("nomad",A17)),ISNUMBER(SEARCH("bayonet",A17)),ISNUMBER(SEARCH("falchion",A17)),ISNUMBER(SEARCH("m9 ",A17)),ISNUMBER(SEARCH("butterfly",A17)),ISNUMBER(SEARCH("skeleton",A17)),ISNUMBER(SEARCH("paracord",A17)),ISNUMBER(SEARCH("classic",A17))), "Knives", OR(ISNUMBER(SEARCH("glove",A17))), "Gloves", OR(ISNUMBER(SEARCH("sticker",A17)),AND(ISNUMBER(SEARCH("fallen",A17)),NOT(ISNUMBER(SEARCH("awp",A17))),NOT(ISNUMBER(SEARCH("ak",A17))))), "Sticker", OR(ISNUMBER(SEARCH("ak ",A17)),ISNUMBER(SEARCH("ak-",A17)),ISNUMBER(SEARCH("m4a1",A17)),ISNUMBER(SEARCH("m4a4",A17)),ISNUMBER(SEARCH("galil",A17)),ISNUMBER(SEARCH("famas",A17))), "Rifles", OR(ISNUMBER(SEARCH("awp",A17)),ISNUMBER(SEARCH("ssg",A17))), "Sniper", OR(ISNUMBER(SEARCH("usp",A17)),ISNUMBER(SEARCH("glock",A17)),ISNUMBER(SEARCH("eagle",A17)),ISNUMBER(SEARCH("p250",A17)),ISNUMBER(SEARCH("berettas",A17))), "Pistol", TRUE, "SMG")} -> Knives | C17: 980 | D17: 1080 | E17: =IF(D17 >0, D17 *0.06, "") -> 64.8 | F17: =IF(D17 >0, D17 -E17, "") -> 1015.2 | G17: =IF(AND(C17>0,F17>0), F17-C17, "") -> 35.2 | H17: =IF(C17>0, G17/C17*100, "") -> 3.5918367
A18: M4a1 Vaporwave | B18: {=_xlfn.IFS(OR(ISNUMBER(SEARCH("survival",A18)),ISNUMBER(SEARCH("nomad",A18)),ISNUMBER(SEARCH("bayonet",A18)),ISNUMBER(SEARCH("falchion",A18)),ISNUMBER(SEARCH("m9 ",A18)),ISNUMBER(SEARCH("butterfly",A18)),ISNUMBER(SEARCH("skeleton",A18)),ISNUMBER(SEARCH("paracord",A18)),ISNUMBER(SEARCH("classic",A18))), "Knives", OR(ISNUMBER(SEARCH("glove",A18))), "Gloves", OR(ISNUMBER(SEARCH("sticker",A18)),AND(ISNUMBER(SEARCH("fallen",A18)),NOT(ISNUMBER(SEARCH("awp",A18))),NOT(ISNUMBER(SEARCH("ak",A18))))), "Sticker", OR(ISNUMBER(SEARCH("ak ",A18)),ISNUMBER(SEARCH("ak-",A18)),ISNUMBER(SEARCH("m4a1",A18)),ISNUMBER(SEARCH("m4a4",A18)),ISNUMBER(SEARCH("galil",A18)),ISNUMBER(SEARCH("famas",A18))), "Rifles", OR(ISNUMBER(SEARCH("awp",A18)),ISNUMBER(SEARCH("ssg",A18))), "Sniper", OR(ISNUMBER(SEARCH("usp",A18)),ISNUMBER(SEARCH("glock",A18)),ISNUMBER(SEARCH("eagle",A18)),ISNUMBER(SEARCH("p250",A18)),ISNUMBER(SEARCH("berettas",A18))), "Pistol", TRUE, "SMG")} -> Rifles | C18: 350 | D18: 418 | E18: =IF(D18 >0, D18 *0.06, "") -> 25.08 | F18: =IF(D18 >0, D18 -E18, "") -> 392.92 | G18: =IF(AND(C18>0,F18>0), F18-C18, "") -> 42.92 | H18: =IF(C18>0, G18/C18*100, "") -> 12.262857
A19: M4a4 Polysoup | B19: {=_xlfn.IFS(OR(ISNUMBER(SEARCH("survival",A19)),ISNUMBER(SEARCH("nomad",A19)),ISNUMBER(SEARCH("bayonet",A19)),ISNUMBER(SEARCH("falchion",A19)),ISNUMBER(SEARCH("m9 ",A19)),ISNUMBER(SEARCH("butterfly",A19)),ISNUMBER(SEARCH("skeleton",A19)),ISNUMBER(SEARCH("paracord",A19)),ISNUMBER(SEARCH("classic",A19))), "Knives", OR(ISNUMBER(SEARCH("glove",A19))), "Gloves", OR(ISNUMBER(SEARCH("sticker",A19)),AND(ISNUMBER(SEARCH("fallen",A19)),NOT(ISNUMBER(SEARCH("awp",A19))),NOT(ISNUMBER(SEARCH("ak",A19))))), "Sticker", OR(ISNUMBER(SEARCH("ak ",A19)),ISNUMBER(SEARCH("ak-",A19)),ISNUMBER(SEARCH("m4a1",A19)),ISNUMBER(SEARCH("m4a4",A19)),ISNUMBER(SEARCH("galil",A19)),ISNUMBER(SEARCH("famas",A19))), "Rifles", OR(ISNUMBER(SEARCH("awp",A19)),ISNUMBER(SEARCH("ssg",A19))), "Sniper", OR(ISNUMBER(SEARCH("usp",A19)),ISNUMBER(SEARCH("glock",A19)),ISNUMBER(SEARCH("eagle",A19)),ISNUMBER(SEARCH("p250",A19)),ISNUMBER(SEARCH("berettas",A19))), "Pistol", TRUE, "SMG")} -> Rifles | C19: 35 | D19: 60 | E19: =IF(D19 >0, D19 *0.06, "") -> 3.6 | F19: =IF(D19 >0, D19 -E19, "") -> 56.4 | G19: =IF(AND(C19>0,F19>0), F19-C19, "") -> 21.4 | H19: =IF(C19>0, G19/C19*100, "") -> 61.142857
A20: Awp Redline Ft St | B20: {=_xlfn.IFS(OR(ISNUMBER(SEARCH("survival",A20)),ISNUMBER(SEARCH("nomad",A20)),ISNUMBER(SEARCH("bayonet",A20)),ISNUMBER(SEARCH("falchion",A20)),ISNUMBER(SEARCH("m9 ",A20)),ISNUMBER(SEARCH("butterfly",A20)),ISNUMBER(SEARCH("skeleton",A20)),ISNUMBER(SEARCH("paracord",A20)),ISNUMBER(SEARCH("classic",A20))), "Knives", OR(ISNUMBER(SEARCH("glove",A20))), "Gloves", OR(ISNUMBER(SEARCH("sticker",A20)),AND(ISNUMBER(SEARCH("fallen",A20)),NOT(ISNUMBER(SEARCH("awp",A20))),NOT(ISNUMBER(SEARCH("ak",A20))))), "Sticker", OR(ISNUMBER(SEARCH("ak ",A20)),ISNUMBER(SEARCH("ak-",A20)),ISNUMBER(SEARCH("m4a1",A20)),ISNUMBER(SEARCH("m4a4",A20)),ISNUMBER(SEARCH("galil",A20)),ISNUMBER(SEARCH("famas",A20))), "Rifles", OR(ISNUMBER(SEARCH("awp",A20)),ISNUMBER(SEARCH("ssg",A20))), "Sniper", OR(ISNUMBER(SEARCH("usp",A20)),ISNUMBER(SEARCH("glock",A20)),ISNUMBER(SEARCH("eagle",A20)),ISNUMBER(SEARCH("p250",A20)),ISNUMBER(SEARCH("berettas",A20))), "Pistol", TRUE, "SMG")} -> Sniper | C20: 685 | D20: 800 | E20: =IF(D20 >0, D20 *0.06, "") -> 48 | F20: =IF(D20 >0, D20 -E20, "") -> 752 | G20: =IF(AND(C20>0,F20>0), F20-C20, "") -> 67 | H20: =IF(C20>0, G20/C20*100, "") -> 9.7810219
A21: Souvenir Charm Strikes Back | B21: Sticker | C21: 200 | D21: 270 | E21: =IF(D21 >0, D21 *0.06, "") -> 16.2 | F21: =IF(D21 >0, D21-E21, "") -> 253.8 | G21: =IF(AND(C21>0,F21>0), F21-C21, "") -> 53.8 | H21: =IF(C21>0, G21/C21*100, "") -> 26.9
A22: Ak Inheritance | B22: Rifles | C22: 350 | D22: 400 | E22: =IF(D22 >0, D22 *0.06, "") -> 24 | F22: =IF(D22 >0, D22-E22, "") -> 376 | G22: =IF(AND(C22>0,F22>0), F22-C22, "") -> 26 | H22: =IF(C22>0, G22/C22*100, "") -> 7.4285714
A23: Mac Neon Rider | B23: {=_xlfn.IFS(OR(ISNUMBER(SEARCH("survival",A23)),ISNUMBER(SEARCH("nomad",A23)),ISNUMBER(SEARCH("bayonet",A23)),ISNUMBER(SEARCH("falchion",A23)),ISNUMBER(SEARCH("m9 ",A23)),ISNUMBER(SEARCH("butterfly",A23)),ISNUMBER(SEARCH("skeleton",A23)),ISNUMBER(SEARCH("paracord",A23)),ISNUMBER(SEARCH("classic",A23))), "Knives", OR(ISNUMBER(SEARCH("glove",A23))), "Gloves", OR(ISNUMBER(SEARCH("sticker",A23)),AND(ISNUMBER(SEARCH("fallen",A23)),NOT(ISNUMBER(SEARCH("awp",A23))),NOT(ISNUMBER(SEARCH("ak",A23))))), "Sticker", OR(ISNUMBER(SEARCH("ak ",A23)),ISNUMBER(SEARCH("ak-",A23)),ISNUMBER(SEARCH("m4a1",A23)),ISNUMBER(SEARCH("m4a4",A23)),ISNUMBER(SEARCH("galil",A23)),ISNUMBER(SEARCH("famas",A23))), "Rifles", OR(ISNUMBER(SEARCH("awp",A23)),ISNUMBER(SEARCH("ssg",A23))), "Sniper", OR(ISNUMBER(SEARCH("usp",A23)),ISNUMBER(SEARCH("glock",A23)),ISNUMBER(SEARCH("eagle",A23)),ISNUMBER(SEARCH("p250",A23)),ISNUMBER(SEARCH("berettas",A23))), "Pistol", TRUE, "SMG")} -> SMG | C23: 50 | D23: 320 | E23: =D23*6% -> 19.2 | F23: =D23-E23 -> 300.8 | G23: =F23-C23 -> 250.8 | H23: =IF(C23>0,(G23/C23)*100,0) -> 501.6
A24: Mp9 Starlight Protector | B24: {=_xlfn.IFS(OR(ISNUMBER(SEARCH("survival",A24)),ISNUMBER(SEARCH("nomad",A24)),ISNUMBER(SEARCH("bayonet",A24)),ISNUMBER(SEARCH("falchion",A24)),ISNUMBER(SEARCH("m9 ",A24)),ISNUMBER(SEARCH("butterfly",A24)),ISNUMBER(SEARCH("skeleton",A24)),ISNUMBER(SEARCH("paracord",A24)),ISNUMBER(SEARCH("classic",A24))), "Knives", OR(ISNUMBER(SEARCH("glove",A24))), "Gloves", OR(ISNUMBER(SEARCH("sticker",A24)),AND(ISNUMBER(SEARCH("fallen",A24)),NOT(ISNUMBER(SEARCH("awp",A24))),NOT(ISNUMBER(SEARCH("ak",A24))))), "Sticker", OR(ISNUMBER(SEARCH("ak ",A24)),ISNUMBER(SEARCH("ak-",A24)),ISNUMBER(SEARCH("m4a1",A24)),ISNUMBER(SEARCH("m4a4",A24)),ISNUMBER(SEARCH("galil",A24)),ISNUMBER(SEARCH("famas",A24))), "Rifles", OR(ISNUMBER(SEARCH("awp",A24)),ISNUMBER(SEARCH("ssg",A24))), "Sniper", OR(ISNUMBER(SEARCH("usp",A24)),ISNUMBER(SEARCH("glock",A24)),ISNUMBER(SEARCH("eagle",A24)),ISNUMBER(SEARCH("p250",A24)),ISNUMBER(SEARCH("berettas",A24))), "Pistol", TRUE, "SMG")} -> SMG | C24: 50 | D24: 300 | E24: =D24*6% -> 18 | F24: =D24-E24 -> 282 | G24: =F24-C24 -> 232 | H24: =IF(C24>0,(G24/C24)*100,0) -> 464
A25: Famas Bad Trip | B25: {=_xlfn.IFS(OR(ISNUMBER(SEARCH("survival",A25)),ISNUMBER(SEARCH("nomad",A25)),ISNUMBER(SEARCH("bayonet",A25)),ISNUMBER(SEARCH("falchion",A25)),ISNUMBER(SEARCH("m9 ",A25)),ISNUMBER(SEARCH("butterfly",A25)),ISNUMBER(SEARCH("skeleton",A25)),ISNUMBER(SEARCH("paracord",A25)),ISNUMBER(SEARCH("classic",A25))), "Knives", OR(ISNUMBER(SEARCH("glove",A25))), "Gloves", OR(ISNUMBER(SEARCH("sticker",A25)),AND(ISNUMBER(SEARCH("fallen",A25)),NOT(ISNUMBER(SEARCH("awp",A25))),NOT(ISNUMBER(SEARCH("ak",A25))))), "Sticker", OR(ISNUMBER(SEARCH("ak ",A25)),ISNUMBER(SEARCH("ak-",A25)),ISNUMBER(SEARCH("m4a1",A25)),ISNUMBER(SEARCH("m4a4",A25)),ISNUMBER(SEARCH("galil",A25)),ISNUMBER(SEARCH("famas",A25))), "Rifles", OR(ISNUMBER(SEARCH("awp",A25)),ISNUMBER(SEARCH("ssg",A25))), "Sniper", OR(ISNUMBER(SEARCH("usp",A25)),ISNUMBER(SEARCH("glock",A25)),ISNUMBER(SEARCH("eagle",A25)),ISNUMBER(SEARCH("p250",A25)),ISNUMBER(SEARCH("berettas",A25))), "Pistol", TRUE, "SMG")} -> Rifles | C25: 40 | D25: 300 | E25: =D25*6% -> 18 | F25: =D25-E25 -> 282 | G25: =F25-C25 -> 242 | H25: =IF(C25>0,(G25/C25)*100,0) -> 605
A26: Ssg Dragonfire | B26: {=_xlfn.IFS(OR(ISNUMBER(SEARCH("survival",A26)),ISNUMBER(SEARCH("nomad",A26)),ISNUMBER(SEARCH("bayonet",A26)),ISNUMBER(SEARCH("falchion",A26)),ISNUMBER(SEARCH("m9 ",A26)),ISNUMBER(SEARCH("butterfly",A26)),ISNUMBER(SEARCH("skeleton",A26)),ISNUMBER(SEARCH("paracord",A26)),ISNUMBER(SEARCH("classic",A26))), "Knives", OR(ISNUMBER(SEARCH("glove",A26))), "Gloves", OR(ISNUMBER(SEARCH("sticker",A26)),AND(ISNUMBER(SEARCH("fallen",A26)),NOT(ISNUMBER(SEARCH("awp",A26))),NOT(ISNUMBER(SEARCH("ak",A26))))), "Sticker", OR(ISNUMBER(SEARCH("ak ",A26)),ISNUMBER(SEARCH("ak-",A26)),ISNUMBER(SEARCH("m4a1",A26)),ISNUMBER(SEARCH("m4a4",A26)),ISNUMBER(SEARCH("galil",A26)),ISNUMBER(SEARCH("famas",A26))), "Rifles", OR(ISNUMBER(SEARCH("awp",A26)),ISNUMBER(SEARCH("ssg",A26))), "Sniper", OR(ISNUMBER(SEARCH("usp",A26)),ISNUMBER(SEARCH("glock",A26)),ISNUMBER(SEARCH("eagle",A26)),ISNUMBER(SEARCH("p250",A26)),ISNUMBER(SEARCH("berettas",A26))), "Pistol", TRUE, "SMG")} -> Sniper | C26: 150 | D26: 300 | E26: =D26*6% -> 18 | F26: =D26-E26 -> 282 | G26: =F26-C26 -> 132 | H26: =IF(C26>0,(G26/C26)*100,0) -> 88
A27: M4a1 Cyrex | B27: {=_xlfn.IFS(OR(ISNUMBER(SEARCH("survival",A27)),ISNUMBER(SEARCH("nomad",A27)),ISNUMBER(SEARCH("bayonet",A27)),ISNUMBER(SEARCH("falchion",A27)),ISNUMBER(SEARCH("m9 ",A27)),ISNUMBER(SEARCH("butterfly",A27)),ISNUMBER(SEARCH("skeleton",A27)),ISNUMBER(SEARCH("paracord",A27)),ISNUMBER(SEARCH("classic",A27))), "Knives", OR(ISNUMBER(SEARCH("glove",A27))), "Gloves", OR(ISNUMBER(SEARCH("sticker",A27)),AND(ISNUMBER(SEARCH("fallen",A27)),NOT(ISNUMBER(SEARCH("awp",A27))),NOT(ISNUMBER(SEARCH("ak",A27))))), "Sticker", OR(ISNUMBER(SEARCH("ak ",A27)),ISNUMBER(SEARCH("ak-",A27)),ISNUMBER(SEARCH("m4a1",A27)),ISNUMBER(SEARCH("m4a4",A27)),ISNUMBER(SEARCH("galil",A27)),ISNUMBER(SEARCH("famas",A27))), "Rifles", OR(ISNUMBER(SEARCH("awp",A27)),ISNUMBER(SEARCH("ssg",A27))), "Sniper", OR(ISNUMBER(SEARCH("usp",A27)),ISNUMBER(SEARCH("glock",A27)),ISNUMBER(SEARCH("eagle",A27)),ISNUMBER(SEARCH("p250",A27)),ISNUMBER(SEARCH("berettas",A27))), "Pistol", TRUE, "SMG")} -> Rifles | C27: 250 | D27: 600 | E27: =D27*6% -> 36 | F27: =D27-E27 -> 564 | G27: =F27-C27 -> 314 | H27: =IF(C27>0,(G27/C27)*100,0) -> 125.6
A28: Mac Neon Rider | B28: {=_xlfn.IFS(OR(ISNUMBER(SEARCH("survival",A28)),ISNUMBER(SEARCH("nomad",A28)),ISNUMBER(SEARCH("bayonet",A28)),ISNUMBER(SEARCH("falchion",A28)),ISNUMBER(SEARCH("m9 ",A28)),ISNUMBER(SEARCH("butterfly",A28)),ISNUMBER(SEARCH("skeleton",A28)),ISNUMBER(SEARCH("paracord",A28)),ISNUMBER(SEARCH("classic",A28))), "Knives", OR(ISNUMBER(SEARCH("glove",A28))), "Gloves", OR(ISNUMBER(SEARCH("sticker",A28)),AND(ISNUMBER(SEARCH("fallen",A28)),NOT(ISNUMBER(SEARCH("awp",A28))),NOT(ISNUMBER(SEARCH("ak",A28))))), "Sticker", OR(ISNUMBER(SEARCH("ak ",A28)),ISNUMBER(SEARCH("ak-",A28)),ISNUMBER(SEARCH("m4a1",A28)),ISNUMBER(SEARCH("m4a4",A28)),ISNUMBER(SEARCH("galil",A28)),ISNUMBER(SEARCH("famas",A28))), "Rifles", OR(ISNUMBER(SEARCH("awp",A28)),ISNUMBER(SEARCH("ssg",A28))), "Sniper", OR(ISNUMBER(SEARCH("usp",A28)),ISNUMBER(SEARCH("glock",A28)),ISNUMBER(SEARCH("eagle",A28)),ISNUMBER(SEARCH("p250",A28)),ISNUMBER(SEARCH("berettas",A28))), "Pistol", TRUE, "SMG")} -> SMG | C28: 60 | D28: 320 | E28: =D28*6% -> 19.2 | F28: =D28-E28 -> 300.8 | G28: =F28-C28 -> 240.8 | H28: =IF(C28>0,(G28/C28)*100,0) -> 401.33333
A29: Bizon Anubis | B29: {=_xlfn.IFS(OR(ISNUMBER(SEARCH("survival",A29)),ISNUMBER(SEARCH("nomad",A29)),ISNUMBER(SEARCH("bayonet",A29)),ISNUMBER(SEARCH("falchion",A29)),ISNUMBER(SEARCH("m9 ",A29)),ISNUMBER(SEARCH("butterfly",A29)),ISNUMBER(SEARCH("skeleton",A29)),ISNUMBER(SEARCH("paracord",A29)),ISNUMBER(SEARCH("classic",A29))), "Knives", OR(ISNUMBER(SEARCH("glove",A29))), "Gloves", OR(ISNUMBER(SEARCH("sticker",A29)),AND(ISNUMBER(SEARCH("fallen",A29)),NOT(ISNUMBER(SEARCH("awp",A29))),NOT(ISNUMBER(SEARCH("ak",A29))))), "Sticker", OR(ISNUMBER(SEARCH("ak ",A29)),ISNUMBER(SEARCH("ak-",A29)),ISNUMBER(SEARCH("m4a1",A29)),ISNUMBER(SEARCH("m4a4",A29)),ISNUMBER(SEARCH("galil",A29)),ISNUMBER(SEARCH("famas",A29))), "Rifles", OR(ISNUMBER(SEARCH("awp",A29)),ISNUMBER(SEARCH("ssg",A29))), "Sniper", OR(ISNUMBER(SEARCH("usp",A29)),ISNUMBER(SEARCH("glock",A29)),ISNUMBER(SEARCH("eagle",A29)),ISNUMBER(SEARCH("p250",A29)),ISNUMBER(SEARCH("berettas",A29))), "Pistol", TRUE, "SMG")} -> SMG | C29: 130 | D29: 500 | E29: =D29*6% -> 30 | F29: =D29-E29 -> 470 | G29: =F29-C29 -> 340 | H29: =IF(C29>0,(G29/C29)*100,0) -> 261.53846
A30: Bizon Anubis | B30: {=_xlfn.IFS(OR(ISNUMBER(SEARCH("survival",A30)),ISNUMBER(SEARCH("nomad",A30)),ISNUMBER(SEARCH("bayonet",A30)),ISNUMBER(SEARCH("falchion",A30)),ISNUMBER(SEARCH("m9 ",A30)),ISNUMBER(SEARCH("butterfly",A30)),ISNUMBER(SEARCH("skeleton",A30)),ISNUMBER(SEARCH("paracord",A30)),ISNUMBER(SEARCH("classic",A30))), "Knives", OR(ISNUMBER(SEARCH("glove",A30))), "Gloves", OR(ISNUMBER(SEARCH("sticker",A30)),AND(ISNUMBER(SEARCH("fallen",A30)),NOT(ISNUMBER(SEARCH("awp",A30))),NOT(ISNUMBER(SEARCH("ak",A30))))), "Sticker", OR(ISNUMBER(SEARCH("ak ",A30)),ISNUMBER(SEARCH("ak-",A30)),ISNUMBER(SEARCH("m4a1",A30)),ISNUMBER(SEARCH("m4a4",A30)),ISNUMBER(SEARCH("galil",A30)),ISNUMBER(SEARCH("famas",A30))), "Rifles", OR(ISNUMBER(SEARCH("awp",A30)),ISNUMBER(SEARCH("ssg",A30))), "Sniper", OR(ISNUMBER(SEARCH("usp",A30)),ISNUMBER(SEARCH("glock",A30)),ISNUMBER(SEARCH("eagle",A30)),ISNUMBER(SEARCH("p250",A30)),ISNUMBER(SEARCH("berettas",A30))), "Pistol", TRUE, "SMG")} -> SMG | C30: 130 | D30: 500 | E30: =D30*6% -> 30 | F30: =D30-E30 -> 470 | G30: =F30-C30 -> 340 | H30: =IF(C30>0,(G30/C30)*100,0) -> 261.53846
A31: Ssg Dragonfire | B31: {=_xlfn.IFS(OR(ISNUMBER(SEARCH("survival",A31)),ISNUMBER(SEARCH("nomad",A31)),ISNUMBER(SEARCH("bayonet",A31)),ISNUMBER(SEARCH("falchion",A31)),ISNUMBER(SEARCH("m9 ",A31)),ISNUMBER(SEARCH("butterfly",A31)),ISNUMBER(SEARCH("skeleton",A31)),ISNUMBER(SEARCH("paracord",A31)),ISNUMBER(SEARCH("classic",A31))), "Knives", OR(ISNUMBER(SEARCH("glove",A31))), "Gloves", OR(ISNUMBER(SEARCH("sticker",A31)),AND(ISNUMBER(SEARCH("fallen",A31)),NOT(ISNUMBER(SEARCH("awp",A31))),NOT(ISNUMBER(SEARCH("ak",A31))))), "Sticker", OR(ISNUMBER(SEARCH("ak ",A31)),ISNUMBER(SEARCH("ak-",A31)),ISNUMBER(SEARCH("m4a1",A31)),ISNUMBER(SEARCH("m4a4",A31)),ISNUMBER(SEARCH("galil",A31)),ISNUMBER(SEARCH("famas",A31))), "Rifles", OR(ISNUMBER(SEARCH("awp",A31)),ISNUMBER(SEARCH("ssg",A31))), "Sniper", OR(ISNUMBER(SEARCH("usp",A31)),ISNUMBER(SEARCH("glock",A31)),ISNUMBER(SEARCH("eagle",A31)),ISNUMBER(SEARCH("p250",A31)),ISNUMBER(SEARCH("berettas",A31))), "Pistol", TRUE, "SMG")} -> Sniper | C31: 610 | D31: 1480 | E31: =D31*6% -> 88.8 | F31: =D31-E31 -> 1391.2 | G31: =F31-C31 -> 781.2 | H31: =IF(C31>0,(G31/C31)*100,0) -> 128.06557
A32: Famas Mecha | B32: {=_xlfn.IFS(OR(ISNUMBER(SEARCH("survival",A32)),ISNUMBER(SEARCH("nomad",A32)),ISNUMBER(SEARCH("bayonet",A32)),ISNUMBER(SEARCH("falchion",A32)),ISNUMBER(SEARCH("m9 ",A32)),ISNUMBER(SEARCH("butterfly",A32)),ISNUMBER(SEARCH("skeleton",A32)),ISNUMBER(SEARCH("paracord",A32)),ISNUMBER(SEARCH("classic",A32))), "Knives", OR(ISNUMBER(SEARCH("glove",A32))), "Gloves", OR(ISNUMBER(SEARCH("sticker",A32)),AND(ISNUMBER(SEARCH("fallen",A32)),NOT(ISNUMBER(SEARCH("awp",A32))),NOT(ISNUMBER(SEARCH("ak",A32))))), "Sticker", OR(ISNUMBER(SEARCH("ak ",A32)),ISNUMBER(SEARCH("ak-",A32)),ISNUMBER(SEARCH("m4a1",A32)),ISNUMBER(SEARCH("m4a4",A32)),ISNUMBER(SEARCH("galil",A32)),ISNUMBER(SEARCH("famas",A32))), "Rifles", OR(ISNUMBER(SEARCH("awp",A32)),ISNUMBER(SEARCH("ssg",A32))), "Sniper", OR(ISNUMBER(SEARCH("usp",A32)),ISNUMBER(SEARCH("glock",A32)),ISNUMBER(SEARCH("eagle",A32)),ISNUMBER(SEARCH("p250",A32)),ISNUMBER(SEARCH("berettas",A32))), "Pistol", TRUE, "SMG")} -> Rifles | C32: 470 | D32: 900 | E32: =D32*6% -> 54 | F32: =D32-E32 -> 846 | G32: =F32-C32 -> 376 | H32: =IF(C32>0,(G32/C32)*100,0) -> 80
A33: Awp Man O War | B33: {=_xlfn.IFS(OR(ISNUMBER(SEARCH("survival",A33)),ISNUMBER(SEARCH("nomad",A33)),ISNUMBER(SEARCH("bayonet",A33)),ISNUMBER(SEARCH("falchion",A33)),ISNUMBER(SEARCH("m9 ",A33)),ISNUMBER(SEARCH("butterfly",A33)),ISNUMBER(SEARCH("skeleton",A33)),ISNUMBER(SEARCH("paracord",A33)),ISNUMBER(SEARCH("classic",A33))), "Knives", OR(ISNUMBER(SEARCH("glove",A33))), "Gloves", OR(ISNUMBER(SEARCH("sticker",A33)),AND(ISNUMBER(SEARCH("fallen",A33)),NOT(ISNUMBER(SEARCH("awp",A33))),NOT(ISNUMBER(SEARCH("ak",A33))))), "Sticker", OR(ISNUMBER(SEARCH("ak ",A33)),ISNUMBER(SEARCH("ak-",A33)),ISNUMBER(SEARCH("m4a1",A33)),ISNUMBER(SEARCH("m4a4",A33)),ISNUMBER(SEARCH("galil",A33)),ISNUMBER(SEARCH("famas",A33))), "Rifles", OR(ISNUMBER(SEARCH("awp",A33)),ISNUMBER(SEARCH("ssg",A33))), "Sniper", OR(ISNUMBER(SEARCH("usp",A33)),ISNUMBER(SEARCH("glock",A33)),ISNUMBER(SEARCH("eagle",A33)),ISNUMBER(SEARCH("p250",A33)),ISNUMBER(SEARCH("berettas",A33))), "Pistol", TRUE, "SMG")} -> Sniper | C33: 350 | D33: 450 | E33: =D33*6% -> 27 | F33: =D33-E33 -> 423 | G33: =F33-C33 -> 73 | H33: =IF(C33>0,(G33/C33)*100,0) -> 20.857143
A34: Awp Redline Ft St | B34: {=_xlfn.IFS(OR(ISNUMBER(SEARCH("survival",A34)),ISNUMBER(SEARCH("nomad",A34)),ISNUMBER(SEARCH("bayonet",A34)),ISNUMBER(SEARCH("falchion",A34)),ISNUMBER(SEARCH("m9 ",A34)),ISNUMBER(SEARCH("butterfly",A34)),ISNUMBER(SEARCH("skeleton",A34)),ISNUMBER(SEARCH("paracord",A34)),ISNUMBER(SEARCH("classic",A34))), "Knives", OR(ISNUMBER(SEARCH("glove",A34))), "Gloves", OR(ISNUMBER(SEARCH("sticker",A34)),AND(ISNUMBER(SEARCH("fallen",A34)),NOT(ISNUMBER(SEARCH("awp",A34))),NOT(ISNUMBER(SEARCH("ak",A34))))), "Sticker", OR(ISNUMBER(SEARCH("ak ",A34)),ISNUMBER(SEARCH("ak-",A34)),ISNUMBER(SEARCH("m4a1",A34)),ISNUMBER(SEARCH("m4a4",A34)),ISNUMBER(SEARCH("galil",A34)),ISNUMBER(SEARCH("famas",A34))), "Rifles", OR(ISNUMBER(SEARCH("awp",A34)),ISNUMBER(SEARCH("ssg",A34))), "Sniper", OR(ISNUMBER(SEARCH("usp",A34)),ISNUMBER(SEARCH("glock",A34)),ISNUMBER(SEARCH("eagle",A34)),ISNUMBER(SEARCH("p250",A34)),ISNUMBER(SEARCH("berettas",A34))), "Pistol", TRUE, "SMG")} -> Sniper | C34: 800 | D34: 950 | E34: =D34*6% -> 57 | F34: =D34-E34 -> 893 | G34: =F34-C34 -> 93 | H34: =IF(C34>0,(G34/C34)*100,0) -> 11.625
... A77: Ak B The Monster | B77: {=_xlfn.IFS(OR(ISNUMBER(SEARCH("survival",A77)),ISNUMBER(SEARCH("nomad",A77)),ISNUMBER(SEARCH("bayonet",A77)),ISNUMBER(SEARCH("falchion",A77)),ISNUMBER(SEARCH("m9 ",A77)),ISNUMBER(SEARCH("butterfly",A77)),ISNUMBER(SEARCH("skeleton",A77)),ISNUMBER(SEARCH("paracord",A77)),ISNUMBER(SEARCH("classic",A77))), "Knives", OR(ISNUMBER(SEARCH("glove",A77))), "Gloves", OR(ISNUMBER(SEARCH("sticker",A77)),AND(ISNUMBER(SEARCH("fallen",A77)),NOT(ISNUMBER(SEARCH("awp",A77))),NOT(ISNUMBER(SEARCH("ak",A77))))), "Sticker", OR(ISNUMBER(SEARCH("ak ",A77)),ISNUMBER(SEARCH("ak-",A77)),ISNUMBER(SEARCH("m4a1",A77)),ISNUMBER(SEARCH("m4a4",A77)),ISNUMBER(SEARCH("galil",A77)),ISNUMBER(SEARCH("famas",A77))), "Rifles", OR(ISNUMBER(SEARCH("awp",A77)),ISNUMBER(SEARCH("ssg",A77))), "Sniper", OR(ISNUMBER(SEARCH("usp",A77)),ISNUMBER(SEARCH("glock",A77)),ISNUMBER(SEARCH("eagle",A77)),ISNUMBER(SEARCH("p250",A77)),ISNUMBER(SEARCH("berettas",A77))), "Pistol", TRUE, "SMG")} -> Rifles | C77: 1400 | D77: 1060 | E77: =D77*6% -> 63.6 | F77: =D77-E77 -> 996.4 | G77: =F77-C77 -> -403.6 | H77: =IF(C77>0,(G77/C77)*100,0) -> -28.828571
A78: Sticker Fallen Gold | B78: {=_xlfn.IFS(OR(ISNUMBER(SEARCH("survival",A78)),ISNUMBER(SEARCH("nomad",A78)),ISNUMBER(SEARCH("bayonet",A78)),ISNUMBER(SEARCH("falchion",A78)),ISNUMBER(SEARCH("m9 ",A78)),ISNUMBER(SEARCH("butterfly",A78)),ISNUMBER(SEARCH("skeleton",A78)),ISNUMBER(SEARCH("paracord",A78)),ISNUMBER(SEARCH("classic",A78))), "Knives", OR(ISNUMBER(SEARCH("glove",A78))), "Gloves", OR(ISNUMBER(SEARCH("sticker",A78)),AND(ISNUMBER(SEARCH("fallen",A78)),NOT(ISNUMBER(SEARCH("awp",A78))),NOT(ISNUMBER(SEARCH("ak",A78))))), "Sticker", OR(ISNUMBER(SEARCH("ak ",A78)),ISNUMBER(SEARCH("ak-",A78)),ISNUMBER(SEARCH("m4a1",A78)),ISNUMBER(SEARCH("m4a4",A78)),ISNUMBER(SEARCH("galil",A78)),ISNUMBER(SEARCH("famas",A78))), "Rifles", OR(ISNUMBER(SEARCH("awp",A78)),ISNUMBER(SEARCH("ssg",A78))), "Sniper", OR(ISNUMBER(SEARCH("usp",A78)),ISNUMBER(SEARCH("glock",A78)),ISNUMBER(SEARCH("eagle",A78)),ISNUMBER(SEARCH("p250",A78)),ISNUMBER(SEARCH("berettas",A78))), "Pistol", TRUE, "SMG")} -> Sticker | C78: 700 | D78: 1400 | E78: =D78*6% -> 84 | F78: =D78-E78 -> 1316 | G78: =F78-C78 -> 616 | H78: =IF(C78>0,(G78/C78)*100,0) -> 88 | L78: LUCRO TOTAL | M78: =SUM(G2:G101) -> 9901.5
A79: Survival Marble Fade | B79: {=_xlfn.IFS(OR(ISNUMBER(SEARCH("survival",A79)),ISNUMBER(SEARCH("nomad",A79)),ISNUMBER(SEARCH("bayonet",A79)),ISNUMBER(SEARCH("falchion",A79)),ISNUMBER(SEARCH("m9 ",A79)),ISNUMBER(SEARCH("butterfly",A79)),ISNUMBER(SEARCH("skeleton",A79)),ISNUMBER(SEARCH("paracord",A79)),ISNUMBER(SEARCH("classic",A79))), "Knives", OR(ISNUMBER(SEARCH("glove",A79))), "Gloves", OR(ISNUMBER(SEARCH("sticker",A79)),AND(ISNUMBER(SEARCH("fallen",A79)),NOT(ISNUMBER(SEARCH("awp",A79))),NOT(ISNUMBER(SEARCH("ak",A79))))), "Sticker", OR(ISNUMBER(SEARCH("ak ",A79)),ISNUMBER(SEARCH("ak-",A79)),ISNUMBER(SEARCH("m4a1",A79)),ISNUMBER(SEARCH("m4a4",A79)),ISNUMBER(SEARCH("galil",A79)),ISNUMBER(SEARCH("famas",A79))), "Rifles", OR(ISNUMBER(SEARCH("awp",A79)),ISNUMBER(SEARCH("ssg",A79))), "Sniper", OR(ISNUMBER(SEARCH("usp",A79)),ISNUMBER(SEARCH("glock",A79)),ISNUMBER(SEARCH("eagle",A79)),ISNUMBER(SEARCH("p250",A79)),ISNUMBER(SEARCH("berettas",A79))), "Pistol", TRUE, "SMG")} -> Knives | C79: 720 | D79: 850 | E79: =D79*6% -> 51 | F79: =D79-E79 -> 799 | G79: =F79-C79 -> 79 | H79: =IF(C79>0,(G79/C79)*100,0) -> 10.972222
A80: Eagle Heat Treated | B80: {=_xlfn.IFS(OR(ISNUMBER(SEARCH("survival",A80)),ISNUMBER(SEARCH("nomad",A80)),ISNUMBER(SEARCH("bayonet",A80)),ISNUMBER(SEARCH("falchion",A80)),ISNUMBER(SEARCH("m9 ",A80)),ISNUMBER(SEARCH("butterfly",A80)),ISNUMBER(SEARCH("skeleton",A80)),ISNUMBER(SEARCH("paracord",A80)),ISNUMBER(SEARCH("classic",A80))), "Knives", OR(ISNUMBER(SEARCH("glove",A80))), "Gloves", OR(ISNUMBER(SEARCH("sticker",A80)),AND(ISNUMBER(SEARCH("fallen",A80)),NOT(ISNUMBER(SEARCH("awp",A80))),NOT(ISNUMBER(SEARCH("ak",A80))))), "Sticker", OR(ISNUMBER(SEARCH("ak ",A80)),ISNUMBER(SEARCH("ak-",A80)),ISNUMBER(SEARCH("m4a1",A80)),ISNUMBER(SEARCH("m4a4",A80)),ISNUMBER(SEARCH("galil",A80)),ISNUMBER(SEARCH("famas",A80))), "Rifles", OR(ISNUMBER(SEARCH("awp",A80)),ISNUMBER(SEARCH("ssg",A80))), "Sniper", OR(ISNUMBER(SEARCH("usp",A80)),ISNUMBER(SEARCH("glock",A80)),ISNUMBER(SEARCH("eagle",A80)),ISNUMBER(SEARCH("p250",A80)),ISNUMBER(SEARCH("berettas",A80))), "Pistol", TRUE, "SMG")} -> Pistol | C80: 150 | D80: 245 | E80: =D80*6% -> 14.7 | F80: =D80-E80 -> 230.3 | G80: =F80-C80 -> 80.3 | H80: =IF(C80>0,(G80/C80)*100,0) -> 53.533333
A81: Survival Marble Fade | B81: {=_xlfn.IFS(OR(ISNUMBER(SEARCH("survival",A81)),ISNUMBER(SEARCH("nomad",A81)),ISNUMBER(SEARCH("bayonet",A81)),ISNUMBER(SEARCH("falchion",A81)),ISNUMBER(SEARCH("m9 ",A81)),ISNUMBER(SEARCH("butterfly",A81)),ISNUMBER(SEARCH("skeleton",A81)),ISNUMBER(SEARCH("paracord",A81)),ISNUMBER(SEARCH("classic",A81))), "Knives", OR(ISNUMBER(SEARCH("glove",A81))), "Gloves", OR(ISNUMBER(SEARCH("sticker",A81)),AND(ISNUMBER(SEARCH("fallen",A81)),NOT(ISNUMBER(SEARCH("awp",A81))),NOT(ISNUMBER(SEARCH("ak",A81))))), "Sticker", OR(ISNUMBER(SEARCH("ak ",A81)),ISNUMBER(SEARCH("ak-",A81)),ISNUMBER(SEARCH("m4a1",A81)),ISNUMBER(SEARCH("m4a4",A81)),ISNUMBER(SEARCH("galil",A81)),ISNUMBER(SEARCH("famas",A81))), "Rifles", OR(ISNUMBER(SEARCH("awp",A81)),ISNUMBER(SEARCH("ssg",A81))), "Sniper", OR(ISNUMBER(SEARCH("usp",A81)),ISNUMBER(SEARCH("glock",A81)),ISNUMBER(SEARCH("eagle",A81)),ISNUMBER(SEARCH("p250",A81)),ISNUMBER(SEARCH("berettas",A81))), "Pistol", TRUE, "SMG")} -> Knives | C81: 700 | D81: 820 | E81: =D81*6% -> 49.2 | F81: =D81-E81 -> 770.8 | G81: =F81-C81 -> 70.8 | H81: =IF(C81>0,(G81/C81)*100,0) -> 10.114286
A82: M4a1-S Fade | B82: {=_xlfn.IFS(OR(ISNUMBER(SEARCH("survival",A82)),ISNUMBER(SEARCH("nomad",A82)),ISNUMBER(SEARCH("bayonet",A82)),ISNUMBER(SEARCH("falchion",A82)),ISNUMBER(SEARCH("m9 ",A82)),ISNUMBER(SEARCH("butterfly",A82)),ISNUMBER(SEARCH("skeleton",A82)),ISNUMBER(SEARCH("paracord",A82)),ISNUMBER(SEARCH("classic",A82))), "Knives", OR(ISNUMBER(SEARCH("glove",A82))), "Gloves", OR(ISNUMBER(SEARCH("sticker",A82)),AND(ISNUMBER(SEARCH("fallen",A82)),NOT(ISNUMBER(SEARCH("awp",A82))),NOT(ISNUMBER(SEARCH("ak",A82))))), "Sticker", OR(ISNUMBER(SEARCH("ak ",A82)),ISNUMBER(SEARCH("ak-",A82)),ISNUMBER(SEARCH("m4a1",A82)),ISNUMBER(SEARCH("m4a4",A82)),ISNUMBER(SEARCH("galil",A82)),ISNUMBER(SEARCH("famas",A82))), "Rifles", OR(ISNUMBER(SEARCH("awp",A82)),ISNUMBER(SEARCH("ssg",A82))), "Sniper", OR(ISNUMBER(SEARCH("usp",A82)),ISNUMBER(SEARCH("glock",A82)),ISNUMBER(SEARCH("eagle",A82)),ISNUMBER(SEARCH("p250",A82)),ISNUMBER(SEARCH("berettas",A82))), "Pistol", TRUE, "SMG")} -> Rifles | C82: 1950 | D82: 2000 | E82: =D82*6% -> 120 | F82: =D82-E82 -> 1880 | G82: =F82-C82 -> -70 | H82: =IF(C82>0,(G82/C82)*100,0) -> -3.5897436
...

Sheet Planilha1
N6: Categoria | O6: Lucro Total | P6: ROI (%)
D7: Categoria | E7: Sniper | N7: Knives | O7: =SUMIF('Controle de Skins'!$B:$B,N7,'Controle de Skins'!$G:$G) -> 1992.68 | P7: =IF(SUMIF('Controle de Skins'!$B:$B,N7,'Controle de Skins'!$C:$C)=0,0,O7/SUMIF('Controle de Skins'!$B:$B,N7,'Controle de Skins'!$C:$C)*100) -> 7.0775351
N8: Gloves | O8: =SUMIF('Controle de Skins'!$B:$B,N8,'Controle de Skins'!$G:$G) -> 119.02 | P8: =IF(SUMIF('Controle de Skins'!$B:$B,N8,'Controle de Skins'!$C:$C)=0,0,O8/SUMIF('Controle de Skins'!$B:$B,N8,'Controle de Skins'!$C:$C)*100) -> 4.8579592
D9: Preço de Compra | E9: =SUMIF('Controle de Skins'!$B:$B,$E$7,'Controle de Skins'!$C:$C) -> 6375 | N9: Sticker | O9: =SUMIF('Controle de Skins'!$B:$B,N9,'Controle de Skins'!$G:$G) -> 1082.84 | P9: =IF(SUMIF('Controle de Skins'!$B:$B,N9,'Controle de Skins'!$C:$C)=0,0,O9/SUMIF('Controle de Skins'!$B:$B,N9,'Controle de Skins'!$C:$C)*100) -> 83.23136
D10: Preço de Venda Bruto | E10: =SUMIF('Controle de Skins'!$B:$B,$E$7,'Controle de Skins'!$D:$D) -> 9430 | N10: Rifles | O10: =SUMIF('Controle de Skins'!$B:$B,N10,'Controle de Skins'!$G:$G) -> 920.02 | P10: =IF(SUMIF('Controle de Skins'!$B:$B,N10,'Controle de Skins'!$C:$C)=0,0,O10/SUMIF('Controle de Skins'!$B:$B,N10,'Controle de Skins'!$C:$C)*100) -> 6.8905033
D11: Taxa (6%) | E11: =SUMIF('Controle de Skins'!$B:$B,$E$7,'Controle de Skins'!$E:$E) -> 565.8 | N11: Sniper | O11: =SUMIF('Controle de Skins'!$B:$B,N11,'Controle de Skins'!$G:$G) -> 2489.2 | P11: =IF(SUMIF('Controle de Skins'!$B:$B,N11,'Controle de Skins'!$C:$C)=0,0,O11/SUMIF('Controle de Skins'!$B:$B,N11,'Controle de Skins'!$C:$C)*100) -> 39.046275
D12: Receita Líquida | E12: =SUMIF('Controle de Skins'!$B:$B,$E$7,'Controle de Skins'!$F:$F) -> 8864.2 | N12: Pistol | O12: =SUMIF('Controle de Skins'!$B:$B,N12,'Controle de Skins'!$G:$G) -> 1797.14 | P12: =IF(SUMIF('Controle de Skins'!$B:$B,N12,'Controle de Skins'!$C:$C)=0,0,O12/SUMIF('Controle de Skins'!$B:$B,N12,'Controle de Skins'!$C:$C)*100) -> 44.264532
D13: Lucro | E13: =SUMIF('Controle de Skins'!$B:$B,$E$7,'Controle de Skins'!$G:$G) -> 2489.2 | N13: SMG | O13: =SUMIF('Controle de Skins'!$B:$B,N13,'Controle de Skins'!$G:$G) -> 1500.6 | P13: =IF(SUMIF('Controle de Skins'!$B:$B,N13,'Controle de Skins'!$C:$C)=0,0,O13/SUMIF('Controle de Skins'!$B:$B,N13,'Controle de Skins'!$C:$C)*100) -> 248.03306
D14: ROI (%) | E14: =IF(E9=0,0,(E13/E9)*100) -> 39.046275
D23: Skin com maior lucro | E23: Valor
D24: {=_xlfn.LET(_xlpm.nomes,_xlfn.UNIQUE('Controle de Skins'!A2:A90),_xlpm.lucros,SUMIF('Controle de Skins'!A2:A90,_xlpm.nomes,'Controle de Skins'!G2:G90),_xlfn.XLOOKUP(MAX(_xlpm.lucros),_xlpm.lucros,_xlpm.nomes))} -> Ssg Dragonfire | E24: {=_xlfn.LET(_xlpm.nomes,_xlfn.UNIQUE('Controle de Skins'!A2:A90),_xlpm.lucros,SUMIF('Controle de Skins'!A2:A90,_xlpm.nomes,'Controle de Skins'!G2:G90),MAX(_xlpm.lucros))} -> 913.2
D26: Skin com maior prejuizo | E26: Valor
D27: {=_xlfn.LET(_xlpm.nomes,_xlfn.UNIQUE('Controle de Skins'!A2:A90),_xlpm.lucros,SUMIF('Controle de Skins'!A2:A90,_xlpm.nomes,'Controle de Skins'!G2:G90),_xlfn.XLOOKUP(MIN(_xlpm.lucros),_xlpm.lucros,_xlpm.nomes))} -> Ak B The Monster | E27: {=_xlfn.LET(_xlpm.nomes,_xlfn.UNIQUE('Controle de Skins'!A2:A90),_xlpm.lucros,SUMIF('Controle de Skins'!A2:A90,_xlpm.nomes,'Controle de Skins'!G2:G90),MIN(_xlpm.lucros))} -> -403.6
